[2025-01-06T13:07:32.004+0000] {local_task_job_runner.py:123} INFO - ::group::Pre task execution logs
[2025-01-06T13:07:32.011+0000] {taskinstance.py:2613} INFO - Dependencies all met for dep_context=non-requeueable deps ti=<TaskInstance: csv_to_mssql_dag.insert_products scheduled__2025-01-06T00:00:00+00:00 [queued]>
[2025-01-06T13:07:32.014+0000] {taskinstance.py:2613} INFO - Dependencies all met for dep_context=requeueable deps ti=<TaskInstance: csv_to_mssql_dag.insert_products scheduled__2025-01-06T00:00:00+00:00 [queued]>
[2025-01-06T13:07:32.014+0000] {taskinstance.py:2866} INFO - Starting attempt 2 of 2
[2025-01-06T13:07:32.019+0000] {taskinstance.py:2889} INFO - Executing <Task(PythonOperator): insert_products> on 2025-01-06 00:00:00+00:00
[2025-01-06T13:07:32.027+0000] {warnings.py:112} WARNING - /home/***/.local/lib/python3.12/site-packages/***/task/task_runner/standard_task_runner.py:70: DeprecationWarning: This process (pid=144) is multi-threaded, use of fork() may lead to deadlocks in the child.
  pid = os.fork()

[2025-01-06T13:07:32.028+0000] {standard_task_runner.py:72} INFO - Started process 145 to run task
[2025-01-06T13:07:32.029+0000] {standard_task_runner.py:104} INFO - Running: ['***', 'tasks', 'run', 'csv_to_mssql_dag', 'insert_products', 'scheduled__2025-01-06T00:00:00+00:00', '--job-id', '19', '--raw', '--subdir', 'DAGS_FOLDER/csv_to_mssql_dag.py', '--cfg-path', '/tmp/tmpq2810ub_']
[2025-01-06T13:07:32.029+0000] {standard_task_runner.py:105} INFO - Job 19: Subtask insert_products
[2025-01-06T13:07:32.324+0000] {task_command.py:467} INFO - Running <TaskInstance: csv_to_mssql_dag.insert_products scheduled__2025-01-06T00:00:00+00:00 [running]> on host ff2cd35e75e1
[2025-01-06T13:07:32.365+0000] {taskinstance.py:3132} INFO - Exporting env vars: AIRFLOW_CTX_DAG_OWNER='***' AIRFLOW_CTX_DAG_ID='csv_to_mssql_dag' AIRFLOW_CTX_TASK_ID='insert_products' AIRFLOW_CTX_EXECUTION_DATE='2025-01-06T00:00:00+00:00' AIRFLOW_CTX_TRY_NUMBER='2' AIRFLOW_CTX_DAG_RUN_ID='scheduled__2025-01-06T00:00:00+00:00'
[2025-01-06T13:07:32.365+0000] {logging_mixin.py:190} INFO - Task instance is in running state
[2025-01-06T13:07:32.366+0000] {logging_mixin.py:190} INFO -  Previous state of the Task instance: queued
[2025-01-06T13:07:32.366+0000] {logging_mixin.py:190} INFO - Current task name:insert_products state:running start_date:2025-01-06 13:07:32.011413+00:00
[2025-01-06T13:07:32.366+0000] {logging_mixin.py:190} INFO - Dag name:csv_to_mssql_dag and current dag run status:running
[2025-01-06T13:07:32.366+0000] {taskinstance.py:731} INFO - ::endgroup::
[2025-01-06T13:07:32.378+0000] {logging_mixin.py:190} INFO - Loaded data from /opt/***/data/Products.csv with 200 rows.
[2025-01-06T13:07:33.053+0000] {logging_mixin.py:190} INFO - Error inserting data from Products.csv into Products: (pyodbc.IntegrityError) ('23000', "[23000] [Microsoft][ODBC Driver 18 for SQL Server][SQL Server]Violation of PRIMARY KEY constraint 'PK__Products__47027DF5E80DB1A0'. Cannot insert duplicate key in object 'dbo.Products'. The duplicate key value is (1). (2627) (SQLExecDirectW)")
[SQL: INSERT INTO [Products] (product_id, product_type, manufacturer_name, location, contact_info) VALUES (?, ?, ?, ?, ?)]
[parameters: ((1, 'Sensor', 'GE Aviation', 'Evendale, OH, USA', 'services@geaviation.com'), (2, 'Propeller', 'Boeing', 'Chicago, IL, USA', 'contact@boeing.com'), (3, 'Sensor', 'Rolls-Royce', 'London, UK', 'queries@rolls-royce.com'), (4, 'Aircraft Lighting', 'Raytheon Technologies', 'Waltham, MA, USA', 'info@raytheon.com'), (5, 'Exhaust System', 'Raytheon Technologies', 'Waltham, MA, USA', 'info@raytheon.com'), (6, 'Fuel Meter', 'GE Aviation', 'Evendale, OH, USA', 'services@geaviation.com'), (7, 'Avionics', 'Rolls-Royce', 'London, UK', 'queries@rolls-royce.com'), (8, 'Aircraft Brake', 'Pratt & Whitney', 'East Hartford, CT, USA', 'help@prattwhitney.com')  ... displaying 10 of 200 total bound parameter sets ...  (199, 'Aircraft Alternator', 'Airbus', 'Toulouse, France', 'contact@airbus.com'), (200, 'Sensor', 'Honeywell Aerospace', 'Charlotte, NC, USA', 'aero@honeywell.com'))]
(Background on this error at: https://sqlalche.me/e/14/gkpj)
[2025-01-06T13:07:33.055+0000] {taskinstance.py:3311} ERROR - Task failed with exception
Traceback (most recent call last):
  File "/home/airflow/.local/lib/python3.12/site-packages/sqlalchemy/engine/base.py", line 1890, in _execute_context
    self.dialect.do_executemany(
  File "/home/airflow/.local/lib/python3.12/site-packages/sqlalchemy/dialects/mssql/pyodbc.py", line 649, in do_executemany
    super(MSDialect_pyodbc, self).do_executemany(
  File "/home/airflow/.local/lib/python3.12/site-packages/sqlalchemy/engine/default.py", line 733, in do_executemany
    cursor.executemany(statement, parameters)
pyodbc.IntegrityError: ('23000', "[23000] [Microsoft][ODBC Driver 18 for SQL Server][SQL Server]Violation of PRIMARY KEY constraint 'PK__Products__47027DF5E80DB1A0'. Cannot insert duplicate key in object 'dbo.Products'. The duplicate key value is (1). (2627) (SQLExecDirectW)")

The above exception was the direct cause of the following exception:

Traceback (most recent call last):
  File "/home/airflow/.local/lib/python3.12/site-packages/airflow/models/taskinstance.py", line 767, in _execute_task
    result = _execute_callable(context=context, **execute_callable_kwargs)
             ^^^^^^^^^^^^^^^^^^^^^^^^^^^^^^^^^^^^^^^^^^^^^^^^^^^^^^^^^^^^^
  File "/home/airflow/.local/lib/python3.12/site-packages/airflow/models/taskinstance.py", line 733, in _execute_callable
    return ExecutionCallableRunner(
           ^^^^^^^^^^^^^^^^^^^^^^^^
  File "/home/airflow/.local/lib/python3.12/site-packages/airflow/utils/operator_helpers.py", line 252, in run
    return self.func(*args, **kwargs)
           ^^^^^^^^^^^^^^^^^^^^^^^^^^
  File "/home/airflow/.local/lib/python3.12/site-packages/airflow/models/baseoperator.py", line 422, in wrapper
    return func(self, *args, **kwargs)
           ^^^^^^^^^^^^^^^^^^^^^^^^^^^
  File "/home/airflow/.local/lib/python3.12/site-packages/airflow/operators/python.py", line 238, in execute
    return_value = self.execute_callable()
                   ^^^^^^^^^^^^^^^^^^^^^^^
  File "/home/airflow/.local/lib/python3.12/site-packages/airflow/operators/python.py", line 256, in execute_callable
    return runner.run(*self.op_args, **self.op_kwargs)
           ^^^^^^^^^^^^^^^^^^^^^^^^^^^^^^^^^^^^^^^^^^^
  File "/home/airflow/.local/lib/python3.12/site-packages/airflow/utils/operator_helpers.py", line 252, in run
    return self.func(*args, **kwargs)
           ^^^^^^^^^^^^^^^^^^^^^^^^^^
  File "/opt/airflow/dags/csv_to_mssql_dag.py", line 41, in insert_data
    df.to_sql(table_name, con=connection, if_exists="append", index=False)
  File "/home/airflow/.local/lib/python3.12/site-packages/pandas/util/_decorators.py", line 333, in wrapper
    return func(*args, **kwargs)
           ^^^^^^^^^^^^^^^^^^^^^
  File "/home/airflow/.local/lib/python3.12/site-packages/pandas/core/generic.py", line 3008, in to_sql
    return sql.to_sql(
           ^^^^^^^^^^^
  File "/home/airflow/.local/lib/python3.12/site-packages/pandas/io/sql.py", line 788, in to_sql
    return pandas_sql.to_sql(
           ^^^^^^^^^^^^^^^^^^
  File "/home/airflow/.local/lib/python3.12/site-packages/pandas/io/sql.py", line 1958, in to_sql
    total_inserted = sql_engine.insert_records(
                     ^^^^^^^^^^^^^^^^^^^^^^^^^^
  File "/home/airflow/.local/lib/python3.12/site-packages/pandas/io/sql.py", line 1507, in insert_records
    raise err
  File "/home/airflow/.local/lib/python3.12/site-packages/pandas/io/sql.py", line 1498, in insert_records
    return table.insert(chunksize=chunksize, method=method)
           ^^^^^^^^^^^^^^^^^^^^^^^^^^^^^^^^^^^^^^^^^^^^^^^^
  File "/home/airflow/.local/lib/python3.12/site-packages/pandas/io/sql.py", line 1059, in insert
    num_inserted = exec_insert(conn, keys, chunk_iter)
                   ^^^^^^^^^^^^^^^^^^^^^^^^^^^^^^^^^^^
  File "/home/airflow/.local/lib/python3.12/site-packages/pandas/io/sql.py", line 951, in _execute_insert
    result = conn.execute(self.table.insert(), data)
             ^^^^^^^^^^^^^^^^^^^^^^^^^^^^^^^^^^^^^^^
  File "/home/airflow/.local/lib/python3.12/site-packages/sqlalchemy/engine/base.py", line 1385, in execute
    return meth(self, multiparams, params, _EMPTY_EXECUTION_OPTS)
           ^^^^^^^^^^^^^^^^^^^^^^^^^^^^^^^^^^^^^^^^^^^^^^^^^^^^^^
  File "/home/airflow/.local/lib/python3.12/site-packages/sqlalchemy/sql/elements.py", line 334, in _execute_on_connection
    return connection._execute_clauseelement(
           ^^^^^^^^^^^^^^^^^^^^^^^^^^^^^^^^^^
  File "/home/airflow/.local/lib/python3.12/site-packages/sqlalchemy/engine/base.py", line 1577, in _execute_clauseelement
    ret = self._execute_context(
          ^^^^^^^^^^^^^^^^^^^^^^
  File "/home/airflow/.local/lib/python3.12/site-packages/sqlalchemy/engine/base.py", line 1953, in _execute_context
    self._handle_dbapi_exception(
  File "/home/airflow/.local/lib/python3.12/site-packages/sqlalchemy/engine/base.py", line 2134, in _handle_dbapi_exception
    util.raise_(
  File "/home/airflow/.local/lib/python3.12/site-packages/sqlalchemy/util/compat.py", line 211, in raise_
    raise exception
  File "/home/airflow/.local/lib/python3.12/site-packages/sqlalchemy/engine/base.py", line 1890, in _execute_context
    self.dialect.do_executemany(
  File "/home/airflow/.local/lib/python3.12/site-packages/sqlalchemy/dialects/mssql/pyodbc.py", line 649, in do_executemany
    super(MSDialect_pyodbc, self).do_executemany(
  File "/home/airflow/.local/lib/python3.12/site-packages/sqlalchemy/engine/default.py", line 733, in do_executemany
    cursor.executemany(statement, parameters)
sqlalchemy.exc.IntegrityError: (pyodbc.IntegrityError) ('23000', "[23000] [Microsoft][ODBC Driver 18 for SQL Server][SQL Server]Violation of PRIMARY KEY constraint 'PK__Products__47027DF5E80DB1A0'. Cannot insert duplicate key in object 'dbo.Products'. The duplicate key value is (1). (2627) (SQLExecDirectW)")
[SQL: INSERT INTO [Products] (product_id, product_type, manufacturer_name, location, contact_info) VALUES (?, ?, ?, ?, ?)]
[parameters: ((1, 'Sensor', 'GE Aviation', 'Evendale, OH, USA', 'services@geaviation.com'), (2, 'Propeller', 'Boeing', 'Chicago, IL, USA', 'contact@boeing.com'), (3, 'Sensor', 'Rolls-Royce', 'London, UK', 'queries@rolls-royce.com'), (4, 'Aircraft Lighting', 'Raytheon Technologies', 'Waltham, MA, USA', 'info@raytheon.com'), (5, 'Exhaust System', 'Raytheon Technologies', 'Waltham, MA, USA', 'info@raytheon.com'), (6, 'Fuel Meter', 'GE Aviation', 'Evendale, OH, USA', 'services@geaviation.com'), (7, 'Avionics', 'Rolls-Royce', 'London, UK', 'queries@rolls-royce.com'), (8, 'Aircraft Brake', 'Pratt & Whitney', 'East Hartford, CT, USA', 'help@prattwhitney.com')  ... displaying 10 of 200 total bound parameter sets ...  (199, 'Aircraft Alternator', 'Airbus', 'Toulouse, France', 'contact@airbus.com'), (200, 'Sensor', 'Honeywell Aerospace', 'Charlotte, NC, USA', 'aero@honeywell.com'))]
(Background on this error at: https://sqlalche.me/e/14/gkpj)
[2025-01-06T13:07:33.076+0000] {logging_mixin.py:190} INFO - Task instance in failure state
[2025-01-06T13:07:33.076+0000] {logging_mixin.py:190} INFO - Task start:2025-01-06 13:07:32.011413+00:00 end:2025-01-06 13:07:33.076221+00:00 duration:1.064808
[2025-01-06T13:07:33.077+0000] {logging_mixin.py:190} INFO - Task:<Task(PythonOperator): insert_products> dag:<DAG: csv_to_mssql_dag> dagrun:<DagRun csv_to_mssql_dag @ 2025-01-06 00:00:00+00:00: scheduled__2025-01-06T00:00:00+00:00, state:running, queued_at: 2025-01-06 13:02:26.742404+00:00. externally triggered: False>
[2025-01-06T13:07:33.077+0000] {logging_mixin.py:190} INFO - Failure caused by (pyodbc.IntegrityError) ('23000', "[23000] [Microsoft][ODBC Driver 18 for SQL Server][SQL Server]Violation of PRIMARY KEY constraint 'PK__Products__47027DF5E80DB1A0'. Cannot insert duplicate key in object 'dbo.Products'. The duplicate key value is (1). (2627) (SQLExecDirectW)")
[SQL: INSERT INTO [Products] (product_id, product_type, manufacturer_name, location, contact_info) VALUES (?, ?, ?, ?, ?)]
[parameters: ((1, 'Sensor', 'GE Aviation', 'Evendale, OH, USA', 'services@geaviation.com'), (2, 'Propeller', 'Boeing', 'Chicago, IL, USA', 'contact@boeing.com'), (3, 'Sensor', 'Rolls-Royce', 'London, UK', 'queries@rolls-royce.com'), (4, 'Aircraft Lighting', 'Raytheon Technologies', 'Waltham, MA, USA', 'info@raytheon.com'), (5, 'Exhaust System', 'Raytheon Technologies', 'Waltham, MA, USA', 'info@raytheon.com'), (6, 'Fuel Meter', 'GE Aviation', 'Evendale, OH, USA', 'services@geaviation.com'), (7, 'Avionics', 'Rolls-Royce', 'London, UK', 'queries@rolls-royce.com'), (8, 'Aircraft Brake', 'Pratt & Whitney', 'East Hartford, CT, USA', 'help@prattwhitney.com')  ... displaying 10 of 200 total bound parameter sets ...  (199, 'Aircraft Alternator', 'Airbus', 'Toulouse, France', 'contact@airbus.com'), (200, 'Sensor', 'Honeywell Aerospace', 'Charlotte, NC, USA', 'aero@honeywell.com'))]
(Background on this error at: https://sqlalche.me/e/14/gkpj)
[2025-01-06T13:07:33.077+0000] {taskinstance.py:1225} INFO - Marking task as FAILED. dag_id=csv_to_mssql_dag, task_id=insert_products, run_id=scheduled__2025-01-06T00:00:00+00:00, execution_date=20250106T000000, start_date=20250106T130732, end_date=20250106T130733
[2025-01-06T13:07:33.084+0000] {taskinstance.py:340} INFO - ::group::Post task execution logs
[2025-01-06T13:07:33.084+0000] {standard_task_runner.py:124} ERROR - Failed to execute job 19 for task insert_products ((pyodbc.IntegrityError) ('23000', "[23000] [Microsoft][ODBC Driver 18 for SQL Server][SQL Server]Violation of PRIMARY KEY constraint 'PK__Products__47027DF5E80DB1A0'. Cannot insert duplicate key in object 'dbo.Products'. The duplicate key value is (1). (2627) (SQLExecDirectW)")
[SQL: INSERT INTO [Products] (product_id, product_type, manufacturer_name, location, contact_info) VALUES (?, ?, ?, ?, ?)]
[parameters: ((1, 'Sensor', 'GE Aviation', 'Evendale, OH, USA', 'services@geaviation.com'), (2, 'Propeller', 'Boeing', 'Chicago, IL, USA', 'contact@boeing.com'), (3, 'Sensor', 'Rolls-Royce', 'London, UK', 'queries@rolls-royce.com'), (4, 'Aircraft Lighting', 'Raytheon Technologies', 'Waltham, MA, USA', 'info@raytheon.com'), (5, 'Exhaust System', 'Raytheon Technologies', 'Waltham, MA, USA', 'info@raytheon.com'), (6, 'Fuel Meter', 'GE Aviation', 'Evendale, OH, USA', 'services@geaviation.com'), (7, 'Avionics', 'Rolls-Royce', 'London, UK', 'queries@rolls-royce.com'), (8, 'Aircraft Brake', 'Pratt & Whitney', 'East Hartford, CT, USA', 'help@prattwhitney.com')  ... displaying 10 of 200 total bound parameter sets ...  (199, 'Aircraft Alternator', 'Airbus', 'Toulouse, France', 'contact@airbus.com'), (200, 'Sensor', 'Honeywell Aerospace', 'Charlotte, NC, USA', 'aero@honeywell.com'))]
(Background on this error at: https://sqlalche.me/e/14/gkpj); 145)
Traceback (most recent call last):
  File "/home/airflow/.local/lib/python3.12/site-packages/sqlalchemy/engine/base.py", line 1890, in _execute_context
    self.dialect.do_executemany(
  File "/home/airflow/.local/lib/python3.12/site-packages/sqlalchemy/dialects/mssql/pyodbc.py", line 649, in do_executemany
    super(MSDialect_pyodbc, self).do_executemany(
  File "/home/airflow/.local/lib/python3.12/site-packages/sqlalchemy/engine/default.py", line 733, in do_executemany
    cursor.executemany(statement, parameters)
pyodbc.IntegrityError: ('23000', "[23000] [Microsoft][ODBC Driver 18 for SQL Server][SQL Server]Violation of PRIMARY KEY constraint 'PK__Products__47027DF5E80DB1A0'. Cannot insert duplicate key in object 'dbo.Products'. The duplicate key value is (1). (2627) (SQLExecDirectW)")

The above exception was the direct cause of the following exception:

Traceback (most recent call last):
  File "/home/airflow/.local/lib/python3.12/site-packages/airflow/task/task_runner/standard_task_runner.py", line 117, in _start_by_fork
    ret = args.func(args, dag=self.dag)
          ^^^^^^^^^^^^^^^^^^^^^^^^^^^^^
  File "/home/airflow/.local/lib/python3.12/site-packages/airflow/cli/cli_config.py", line 49, in command
    return func(*args, **kwargs)
           ^^^^^^^^^^^^^^^^^^^^^
  File "/home/airflow/.local/lib/python3.12/site-packages/airflow/utils/cli.py", line 116, in wrapper
    return f(*args, **kwargs)
           ^^^^^^^^^^^^^^^^^^
  File "/home/airflow/.local/lib/python3.12/site-packages/airflow/cli/commands/task_command.py", line 483, in task_run
    task_return_code = _run_task_by_selected_method(args, _dag, ti)
                       ^^^^^^^^^^^^^^^^^^^^^^^^^^^^^^^^^^^^^^^^^^^^
  File "/home/airflow/.local/lib/python3.12/site-packages/airflow/cli/commands/task_command.py", line 256, in _run_task_by_selected_method
    return _run_raw_task(args, ti)
           ^^^^^^^^^^^^^^^^^^^^^^^
  File "/home/airflow/.local/lib/python3.12/site-packages/airflow/cli/commands/task_command.py", line 341, in _run_raw_task
    return ti._run_raw_task(
           ^^^^^^^^^^^^^^^^^
  File "/home/airflow/.local/lib/python3.12/site-packages/airflow/utils/session.py", line 97, in wrapper
    return func(*args, session=session, **kwargs)
           ^^^^^^^^^^^^^^^^^^^^^^^^^^^^^^^^^^^^^^
  File "/home/airflow/.local/lib/python3.12/site-packages/airflow/models/taskinstance.py", line 3005, in _run_raw_task
    return _run_raw_task(
           ^^^^^^^^^^^^^^
  File "/home/airflow/.local/lib/python3.12/site-packages/airflow/models/taskinstance.py", line 273, in _run_raw_task
    TaskInstance._execute_task_with_callbacks(
  File "/home/airflow/.local/lib/python3.12/site-packages/airflow/models/taskinstance.py", line 3159, in _execute_task_with_callbacks
    result = self._execute_task(context, task_orig)
             ^^^^^^^^^^^^^^^^^^^^^^^^^^^^^^^^^^^^^^
  File "/home/airflow/.local/lib/python3.12/site-packages/airflow/models/taskinstance.py", line 3183, in _execute_task
    return _execute_task(self, context, task_orig)
           ^^^^^^^^^^^^^^^^^^^^^^^^^^^^^^^^^^^^^^^
  File "/home/airflow/.local/lib/python3.12/site-packages/airflow/models/taskinstance.py", line 767, in _execute_task
    result = _execute_callable(context=context, **execute_callable_kwargs)
             ^^^^^^^^^^^^^^^^^^^^^^^^^^^^^^^^^^^^^^^^^^^^^^^^^^^^^^^^^^^^^
  File "/home/airflow/.local/lib/python3.12/site-packages/airflow/models/taskinstance.py", line 733, in _execute_callable
    return ExecutionCallableRunner(
           ^^^^^^^^^^^^^^^^^^^^^^^^
  File "/home/airflow/.local/lib/python3.12/site-packages/airflow/utils/operator_helpers.py", line 252, in run
    return self.func(*args, **kwargs)
           ^^^^^^^^^^^^^^^^^^^^^^^^^^
  File "/home/airflow/.local/lib/python3.12/site-packages/airflow/models/baseoperator.py", line 422, in wrapper
    return func(self, *args, **kwargs)
           ^^^^^^^^^^^^^^^^^^^^^^^^^^^
  File "/home/airflow/.local/lib/python3.12/site-packages/airflow/operators/python.py", line 238, in execute
    return_value = self.execute_callable()
                   ^^^^^^^^^^^^^^^^^^^^^^^
  File "/home/airflow/.local/lib/python3.12/site-packages/airflow/operators/python.py", line 256, in execute_callable
    return runner.run(*self.op_args, **self.op_kwargs)
           ^^^^^^^^^^^^^^^^^^^^^^^^^^^^^^^^^^^^^^^^^^^
  File "/home/airflow/.local/lib/python3.12/site-packages/airflow/utils/operator_helpers.py", line 252, in run
    return self.func(*args, **kwargs)
           ^^^^^^^^^^^^^^^^^^^^^^^^^^
  File "/opt/airflow/dags/csv_to_mssql_dag.py", line 41, in insert_data
    df.to_sql(table_name, con=connection, if_exists="append", index=False)
  File "/home/airflow/.local/lib/python3.12/site-packages/pandas/util/_decorators.py", line 333, in wrapper
    return func(*args, **kwargs)
           ^^^^^^^^^^^^^^^^^^^^^
  File "/home/airflow/.local/lib/python3.12/site-packages/pandas/core/generic.py", line 3008, in to_sql
    return sql.to_sql(
           ^^^^^^^^^^^
  File "/home/airflow/.local/lib/python3.12/site-packages/pandas/io/sql.py", line 788, in to_sql
    return pandas_sql.to_sql(
           ^^^^^^^^^^^^^^^^^^
  File "/home/airflow/.local/lib/python3.12/site-packages/pandas/io/sql.py", line 1958, in to_sql
    total_inserted = sql_engine.insert_records(
                     ^^^^^^^^^^^^^^^^^^^^^^^^^^
  File "/home/airflow/.local/lib/python3.12/site-packages/pandas/io/sql.py", line 1507, in insert_records
    raise err
  File "/home/airflow/.local/lib/python3.12/site-packages/pandas/io/sql.py", line 1498, in insert_records
    return table.insert(chunksize=chunksize, method=method)
           ^^^^^^^^^^^^^^^^^^^^^^^^^^^^^^^^^^^^^^^^^^^^^^^^
  File "/home/airflow/.local/lib/python3.12/site-packages/pandas/io/sql.py", line 1059, in insert
    num_inserted = exec_insert(conn, keys, chunk_iter)
                   ^^^^^^^^^^^^^^^^^^^^^^^^^^^^^^^^^^^
  File "/home/airflow/.local/lib/python3.12/site-packages/pandas/io/sql.py", line 951, in _execute_insert
    result = conn.execute(self.table.insert(), data)
             ^^^^^^^^^^^^^^^^^^^^^^^^^^^^^^^^^^^^^^^
  File "/home/airflow/.local/lib/python3.12/site-packages/sqlalchemy/engine/base.py", line 1385, in execute
    return meth(self, multiparams, params, _EMPTY_EXECUTION_OPTS)
           ^^^^^^^^^^^^^^^^^^^^^^^^^^^^^^^^^^^^^^^^^^^^^^^^^^^^^^
  File "/home/airflow/.local/lib/python3.12/site-packages/sqlalchemy/sql/elements.py", line 334, in _execute_on_connection
    return connection._execute_clauseelement(
           ^^^^^^^^^^^^^^^^^^^^^^^^^^^^^^^^^^
  File "/home/airflow/.local/lib/python3.12/site-packages/sqlalchemy/engine/base.py", line 1577, in _execute_clauseelement
    ret = self._execute_context(
          ^^^^^^^^^^^^^^^^^^^^^^
  File "/home/airflow/.local/lib/python3.12/site-packages/sqlalchemy/engine/base.py", line 1953, in _execute_context
    self._handle_dbapi_exception(
  File "/home/airflow/.local/lib/python3.12/site-packages/sqlalchemy/engine/base.py", line 2134, in _handle_dbapi_exception
    util.raise_(
  File "/home/airflow/.local/lib/python3.12/site-packages/sqlalchemy/util/compat.py", line 211, in raise_
    raise exception
  File "/home/airflow/.local/lib/python3.12/site-packages/sqlalchemy/engine/base.py", line 1890, in _execute_context
    self.dialect.do_executemany(
  File "/home/airflow/.local/lib/python3.12/site-packages/sqlalchemy/dialects/mssql/pyodbc.py", line 649, in do_executemany
    super(MSDialect_pyodbc, self).do_executemany(
  File "/home/airflow/.local/lib/python3.12/site-packages/sqlalchemy/engine/default.py", line 733, in do_executemany
    cursor.executemany(statement, parameters)
sqlalchemy.exc.IntegrityError: (pyodbc.IntegrityError) ('23000', "[23000] [Microsoft][ODBC Driver 18 for SQL Server][SQL Server]Violation of PRIMARY KEY constraint 'PK__Products__47027DF5E80DB1A0'. Cannot insert duplicate key in object 'dbo.Products'. The duplicate key value is (1). (2627) (SQLExecDirectW)")
[SQL: INSERT INTO [Products] (product_id, product_type, manufacturer_name, location, contact_info) VALUES (?, ?, ?, ?, ?)]
[parameters: ((1, 'Sensor', 'GE Aviation', 'Evendale, OH, USA', 'services@geaviation.com'), (2, 'Propeller', 'Boeing', 'Chicago, IL, USA', 'contact@boeing.com'), (3, 'Sensor', 'Rolls-Royce', 'London, UK', 'queries@rolls-royce.com'), (4, 'Aircraft Lighting', 'Raytheon Technologies', 'Waltham, MA, USA', 'info@raytheon.com'), (5, 'Exhaust System', 'Raytheon Technologies', 'Waltham, MA, USA', 'info@raytheon.com'), (6, 'Fuel Meter', 'GE Aviation', 'Evendale, OH, USA', 'services@geaviation.com'), (7, 'Avionics', 'Rolls-Royce', 'London, UK', 'queries@rolls-royce.com'), (8, 'Aircraft Brake', 'Pratt & Whitney', 'East Hartford, CT, USA', 'help@prattwhitney.com')  ... displaying 10 of 200 total bound parameter sets ...  (199, 'Aircraft Alternator', 'Airbus', 'Toulouse, France', 'contact@airbus.com'), (200, 'Sensor', 'Honeywell Aerospace', 'Charlotte, NC, USA', 'aero@honeywell.com'))]
(Background on this error at: https://sqlalche.me/e/14/gkpj)
[2025-01-06T13:07:33.107+0000] {local_task_job_runner.py:266} INFO - Task exited with return code 1
[2025-01-06T13:07:33.233+0000] {taskinstance.py:3895} INFO - 0 downstream tasks scheduled from follow-on schedule check
[2025-01-06T13:07:33.235+0000] {local_task_job_runner.py:245} INFO - ::endgroup::
